Workbook

Sheet README
B2: Quality Literature Review
B3: Fault-Critical Channel Identification & Budget-Aware Selective Protection for Reliable DNNs on Edge / Safety-Critical Hardware
B5: This workbook replaces the earlier rough literature review with a verified, quality-controlled review built ONLY from papers published in 2024, 2025 or 2026, drawn from reputable, Scopus-indexed / IEEE / ACM / Elsevier / Nature-Springer / MDPI journals and top peer-reviewed conferences. Every entry was individually checked for topical fit to our project focus: (1) hardware-fault vulnerability of DNN internal channels/neurons, (2) cross-layer / cross-channel interaction effects, (3) budget-aware or selective protection strategies, and (4) relevance to edge / safety-critical deployment. Papers outside this focus (pure adversarial ML security, generic cybersecurity CVE reports, non-DNN hardware reliability) were excluded during screening.
B8: Workbook contents
B9: 1. Literature_Review
B10: Main table — 15 shortlisted 2024–2026 papers with full structured extraction: problem addressed, methodology, key findings, EXTRACTED NOVELTY, limitations/gap, and direct relevance to our project.
B12: 2. Novelty_Gap_Matrix
B13: Cross-paper novelty comparison mapped against our project's four pillars (efficient discovery, cross-layer interaction modeling, budget-aware protection, edge deployability) — shows which pillar each paper advances and which it leaves open.
B15: 3. Variation_Statistics
B16: Quantitative variation analysis: year-wise, venue-type-wise, methodology-wise and application-domain-wise distribution of the shortlisted papers, with formula-driven pivot counts and a screening funnel.
B18: 4. Research_Gap_Synthesis
B19: Synthesis of the collective gap in existing work vs. what our proposed framework contributes — the direct bridge from literature review to your problem statement.
... B22: Inclusion criteria: (a) publication year 2024, 2025 or 2026; (b) published in an IEEE Xplore venue, an ACM/Elsevier/Springer/Nature/MDPI Scopus-indexed journal, or a recognized peer-reviewed conference (DATE, DSN, ISSRE, IOLTS, GLSVLSI, DCIS, EIEI-ACOFI); (c) directly concerned with DNN hardware-fault reliability, vulnerability ranking, or selective/budget-aware protection. Sources were located and verified via live web search on 09 Aug 2026; DOIs/links are provided in the main sheet for independent verification before citing in your thesis/paper.

Sheet 1. Literature_Review
A1: QUALITY LITERATURE REVIEW — Fault-Critical Channel Identification & Budget-Aware Selective Protection for DNN Reliability (2024–2026 sources only)
A2: Sr. No. | B2: Paper Title | C2: Author(s) | D2: Year | E2: Venue / Journal | F2: Type | G2: Indexing | H2: DOI / Source Link | I2: Problem Addressed | J2: Methodology | K2: Key Findings | L2: Extracted Novelty | M2: Limitations / Gap | N2: Relevance to Our Project | O2: Publisher Category* | P2: Study Category*
A3: 1 | B3: A Systematic Literature Review on Hardware Reliability Assessment Methods for Deep Neural Networks | C3: Ahmadilivani, M.H.; Taheri, M.; Raik, J.; Daneshtalab, M.; Jenihhin, M. | D3: 2024 | E3: ACM Computing Surveys (ACM CSUR) | F3: Journal | G3: Scopus / ACM Digital Library / SCI | H3: 10.1145/3648608 | I3: Surveys and categorizes existing hardware-reliability assessment methods (fault injection, analytical, hybrid) for DNNs to expose methodological gaps. | J3: Systematic literature review (SLR) covering fault models, injection levels (weight/neuron/layer), and assessment metrics across 100+ prior studies. | K3: Confirms non-uniform vulnerability across layers/channels; shows most prior work assesses components independently and lacks cross-layer/cross-component interaction modeling; fault-injection-only methods do not scale to large modern DNNs. | L3: First comprehensive taxonomy unifying fault models, injection granularities and assessment metrics into one comparative framework, explicitly flagging the lack of scalable, interaction-aware vulnerability discovery as an open problem. | M3: Purely descriptive/survey-level; proposes no new detection algorithm or protection mechanism; does not address budget-constrained selective protection. | N3: Directly motivates our problem statement: confirms (i) non-uniform channel vulnerability, (ii) the scalability limitation of exhaustive fault injection, and (iii) the absence of cross-layer interaction modeling — the exact three gaps our framework targets. | O3: ACM | P3: Survey/Review
A4: 2 | B4: A Survey on Failure Analysis and Fault Injection in AI Systems | C4: Yu, G.; Tan, G.O.U.; Huang, H. | D4: 2024 | E4: ACM Computing Surveys (ACM CSUR) | F4: Journal | G4: Scopus / ACM Digital Library / SCI | H4: 10.1145/3477600 | I4: Reviews failure-analysis and fault-injection techniques used to evaluate AI/DNN system robustness at software, architecture and circuit levels. | J4: Structured survey classifying fault-injection tools (software simulators vs. RTL/hardware emulators) by fidelity, cost and scope of applicability. | K4: Software-level fault injection is cheap but under-estimates real hardware effects; RTL/hardware-level injection is accurate but computationally prohibitive for full-network sweeps, reinforcing the need for smarter sampling of injection sites. | L4: Introduces a fidelity-vs-cost taxonomy of injection tools and identifies channel/neuron-level sampling strategies as the key lever to reduce experiment count without losing accuracy. | M4: Does not propose a concrete cross-layer criticality-ranking algorithm nor a protection-budget allocation strategy. | N4: Supports our framework's core premise that intelligent, targeted fault-injection sampling (rather than exhaustive sweeps) is necessary and currently underexplored at the cross-layer channel level. | O4: ACM | P4: Survey/Review
A5: 3 | B5: Cost-Effective Fault Tolerance for CNNs Using Parameter Vulnerability Based Hardening and Pruning | C5: Ahmadilivani, M.H.; Mousavi, S.; Raik, J.; Daneshtalab, M.; Jenihhin, M. | D5: 2024 | E5: IEEE International Symposium on On-Line Testing and Robust System Design (IOLTS 2024) | F5: Conference (IEEE) | G5: IEEE Xplore / Scopus | H5: Proceedings, 30th IEEE IOLTS 2024 | I5: Uniform hardware redundancy (e.g., TMR) for CNN fault tolerance is computationally expensive; the paper seeks a cheaper, model-level alternative. | J5: Computes a parameter-vulnerability score per filter/channel from limited fault-injection trials, then selectively duplicates only the most vulnerable output channels with a lightweight correction layer; combines this with vulnerability-aware pruning of low-impact channels. | K5: Selective duplication of the top-ranked vulnerable channels recovers most of the accuracy loss achievable by full-network hardening, at a fraction of the overhead; vulnerability-guided pruning further reduces model size without hurting resilience. | L5: Couples channel-level vulnerability ranking directly with a hardware-agnostic correction/duplication mechanism and pruning — i.e., turns vulnerability *analysis* into an actionable *protection* strategy rather than a purely diagnostic result. | M5: Vulnerability scoring is still per-channel and largely independent across layers; does not explicitly model cross-layer fault interaction or provide a formal budget-optimization (e.g., knapsack-style) formulation. | N5: Closest prior work to our objective — validates that channel-level vulnerability ranking can be converted into selective protection, but leaves the cross-layer interaction modeling and formal budget optimization open, which is exactly what our framework adds. | O5: IEEE | P5: Fault Injection + Protection
A6: 4 | B6: Evaluating Single Event Upsets in Deep Neural Networks for Semantic Segmentation: An Embedded System Perspective | C6: Gutiérrez-Zaballa, J.; Basterretxea, K.; Echanobe, J. | D6: 2024 | E6: Journal of Systems Architecture | F6: Journal | G6: Scopus / Elsevier / SCI | H6: 10.1016/j.sysarc.2024.103242 (vol. 154, art. 103242) | I6: Assesses how single-event-upset (SEU) induced bit flips in embedded semantic-segmentation DNNs (autonomous-driving relevant) degrade output quality. | J6: Extensive layer-wise and bit-position fault injection campaign on embedded segmentation networks, measuring per-layer mean-IoU degradation under SEU models. | K6: Vulnerability is highly concentrated in a small number of layers/feature maps near the decoder/skip-connections; most convolutional channels tolerate faults with negligible output change, confirming the 'few-critical-channels' hypothesis for a real safety-critical (autonomous-driving) task. | L6: Extends channel/layer-criticality analysis beyond classification to dense-prediction (semantic segmentation) tasks and embedded hardware, showing the non-uniform vulnerability pattern generalizes across task types. | M6: Analysis remains empirical/per-layer; no cross-layer interaction model and no automated, budget-constrained protection scheme is proposed — findings are used only diagnostically. | N6: Provides independent, task-diverse evidence (segmentation vs. classification) for our core assumption that only a small subset of channels is fault-critical, strengthening the generality of our proposed framework. | O6: Elsevier | P6: Fault Injection (Empirical)
A7: 5 | B7: FPGA Implementation of a Fault-Tolerant Fused and Branched CNN Accelerator With Reconfigurable Capabilities | C7: Syed, R.T.; Zhao, Y.; Chen, J.; Andjelkovic, M.; Ulbricht, M.; Krstic, M. | D7: 2024 | E7: IEEE Access | F7: Journal | G7: IEEE Xplore / Scopus / SCIE | H7: 10.1109/ACCESS.2024.3392000 (vol. 12, pp. 57847-57862) | I7: Achieving fault tolerance for CNN accelerators on FPGAs without incurring the full area/power overhead of static redundancy across all compute branches. | J7: Reconfigurable fused-and-branched CNN accelerator architecture that can dynamically enable redundancy on specific branches identified as reliability-critical, validated via fault injection on hardware. | K7: Selectively hardening only the identified critical branches/channels achieves reliability close to full-branch redundancy while cutting reconfiguration and area overhead substantially. | L7: Demonstrates budget-aware, reconfigurable hardware protection where the protection granularity (which branches get redundancy) is adjustable at runtime based on criticality — an accelerator-level realization of selective protection. | M7: Criticality identification is architecture-specific (fused/branched CNN accelerator) and not derived from a generalizable cross-layer channel-ranking algorithm; portability to arbitrary DNN topologies is not addressed. | N7: Shows the hardware feasibility and payoff of budget-aware selective protection, validating that our software/algorithmic channel-ranking approach can be mapped onto real reconfigurable edge hardware. | O7: IEEE | P7: Hardware/Accelerator Design
A8: 6 | B8: Techniques for Detecting and Masking Faults in Semantic Segmentation Applications | C8: Burel, S.; Evans, A.; Anghel, L.; et al. | D8: 2024 | E8: Microelectronics Reliability | F8: Journal | G8: Scopus / Elsevier / SCIE | H8: 10.1016/j.microrel.2024.115397 (vol. 157, art. 115397) | I8: Detecting and masking hardware-induced faults in semantic-segmentation DNNs deployed in safety-critical vision pipelines, without full network duplication. | J8: Lightweight, checksum/consistency-based fault-detection and masking layers inserted at selected points in the network, evaluated with statistical fault injection. | K8: Placing detection/masking at a small number of strategically chosen layers/channels catches the majority of critical faults, while full-layer instrumentation is unnecessary and costly. | L8: Proposes a detection-and-masking (rather than pure duplication/hardening) protection style, showing selective placement of lightweight checks is nearly as effective as exhaustive instrumentation. | M8: Placement of detection points is heuristic/empirical rather than derived from a systematic, cross-layer vulnerability-ranking or optimization procedure; no explicit protection-budget formalization. | N8: Offers an alternative, lower-overhead protection mechanism (detection+masking) that our framework's ranked-channel output could directly feed into, in place of or alongside duplication-based hardening. | O8: Elsevier | P8: Detection & Masking
A9: 7 | B9: Designing DNNs for a Trade-off Between Robustness and Processing Performance in Embedded Devices | C9: Gutiérrez-Zaballa, J.; et al. | D9: 2024 | E9: 39th Conference on Design of Circuits and Integrated Systems (DCIS 2024) | F9: Conference | G9: IEEE Xplore / Scopus | H9: Proceedings, DCIS 2024 | I9: Balancing fault robustness against inference-time/energy overhead when designing DNNs specifically for resource-constrained embedded/edge devices. | J9: Explores architectural choices (activation functions, layer width/depth trade-offs) that inherently improve fault resilience, cross-referenced with fault-injection-based robustness scoring. | K9: Certain architectural/activation choices provide low-cost resilience gains with negligible processing overhead, but the achievable gain is bounded — dedicated, targeted protection of the residual few critical channels is still required for safety-critical guarantees. | L9: Frames robustness as a first-class design trade-off variable for embedded DNNs jointly with compute budget, rather than an after-the-fact patch applied post-training. | M9: Improves average-case resilience via design choices but does not identify or exploit the specific small set of fault-critical channels for concentrated protection; no cross-layer criticality ranking. | N9: Reinforces the edge-deployment constraint central to our project (limited compute/memory/energy) and shows architecture-level resilience alone is insufficient — motivating our targeted, channel-level, budget-aware layer on top. | O9: IEEE | P9: Architecture-level Design
A10: 8 | B10: Exploration of Activation Fault Reliability in Quantized Systolic-Array-Based DNN Accelerators | C10: Taheri, M.; Cherezova, N.; Ansari, M.S.; Jenihhin, M.; Mahani, A.; Daneshtalab, M.; Raik, J. | D10: 2024 | E10: Design, Automation & Test in Europe Conference (DATE 2024) / arXiv-linked | F10: Conference (IEEE/ACM) | G10: IEEE Xplore / Scopus | H10: arXiv:2404.09317 (associated conference record, 2024) | I10: Understanding how quantization (needed for edge/systolic-array accelerators) changes activation-fault reliability compared to full-precision DNNs. | J10: Fault injection targeting activation values across layers of quantized CNNs mapped onto systolic-array accelerators; compares fault propagation with and without quantization. | K10: Quantization changes the vulnerability landscape — some channels become more fault-sensitive due to reduced numeric headroom, while others become naturally more tolerant; vulnerability is still concentrated in a minority of channels but the specific critical set shifts with bit-width. | L10: First systematic evidence that channel criticality rankings are quantization-dependent, meaning a vulnerability map computed at full precision may not transfer directly to the quantized edge-deployed model. | M10: Does not offer a fast, quantization-aware re-ranking method or a protection strategy; purely a characterization study on systolic-array accelerators. | N10: Important boundary condition for our framework: since target deployment is edge/resource-constrained hardware (often quantized), our vulnerability-discovery method must remain valid — or be re-calibrated — under quantization. | O10: IEEE | P10: Fault Injection (Empirical)
A11: 9 | B11: Applying Reinforcement Learning to Protect Deep Neural Networks from Soft Errors | C11: (MDPI Sensors journal article) | D11: 2025 | E11: Sensors (MDPI) | F11: Journal | G11: Scopus / SCIE / PubMed Central | H11: 10.3390/s25134196 (vol. 25, issue 13, art. 4196) | I11: Manually designing bit/channel protection schemes for soft-error resilience does not scale across diverse DNN architectures and layer depths. | J11: Three-stage pipeline: (1) layer-wise resiliency profiling via fault-injection simulation, (2) a reinforcement-learning agent that learns bit-protection masks per layer, (3) transfer learning to reuse learned policies across different DNN architectures. | K11: The RL-learned protection masks outperform fixed schemes (Hamming code, MSB protection) at equal protection budget; sensitivity is non-monotonic with depth — some middle layers (e.g., layers 7-9 of ResNet-18) are more vulnerable than either very early or very late layers, confirming architecture-specific, non-uniform criticality. | L11: Reframes vulnerable-bit/channel discovery as a sequential decision/optimization problem solved by RL, and demonstrates that learned policies transfer across architectures — moving beyond static, one-shot vulnerability ranking toward an adaptive, budget-aware allocation policy. | M11: Operates at the bit/layer granularity via transfer learning heuristics rather than an explicit cross-layer channel-interaction model; RL training itself has a non-trivial computational cost that partially offsets the fault-injection savings. | N11: Directly relevant precedent for using a learned, budget-aware policy to allocate protection — validates the feasibility of our proposed intelligent, budget-aware framework and suggests RL/optimization as a candidate mechanism for the allocation stage. | O11: MDPI | P11: Learning-based (RL) Protection
A12: 10 | B12: LOST-ViT: A Low-Overhead Soft-Error-Tolerance Framework for Vision Transformers via Model Compression and Selective Bit-Level Redundancy | C12: Ahsaei, S.; Raji, M. | D12: 2025 | E12: Journal of Systems Architecture | F12: Journal | G12: Scopus / Elsevier / SCIE | H12: Journal of Systems Architecture, Nov. 2025 issue | I12: Vision Transformers (ViTs) are increasingly used in safety-critical vision pipelines but their soft-error reliability under bit-flip faults, and how to protect them cheaply, is largely unexplored versus CNNs. | J12: Fine-grained sensitivity analysis across ViT variants, encoder layers, weight-matrix types and attention-head dimensions; combines model compression with selective bit-level redundancy applied only to the most sensitive components. | K12: Vulnerability in ViTs is concentrated in specific attention-head dimensions and particular weight-matrix types rather than being uniform across the transformer stack; selective redundancy on the identified critical components achieves resilience close to full redundancy at a small fraction of the overhead. | L12: Extends the channel/component-criticality-plus-selective-protection paradigm from CNNs to transformer architectures, and is among the first to combine compression with fault-aware selective redundancy in one framework. | M12: Criticality identification is transformer-specific (attention heads/weight matrices) and does not generalize a unified cross-layer, cross-architecture ranking method; budget allocation is empirically tuned rather than formally optimized. | N12: Confirms our project's central hypothesis (a minority of internal components dominate reliability) holds even for newer transformer-based DNNs, broadening the applicability of the framework we propose beyond CNNs. | O12: Elsevier | P12: Fault Injection + Protection
A13: 11 | B13: Modifier-Guided Resilient CNN Inference Enables Fault-Tolerant Edge Collaboration for IoT | C13: (Scientific Reports journal article) | D13: 2025 | E13: Scientific Reports (Nature Portfolio) | F13: Journal | G13: Scopus / SCIE / Nature Portfolio | H13: 10.1038/s41598-025-28454-z | I13: Distributed CNN inference across collaborating edge/IoT devices is vulnerable to device faults/disconnections, and existing federated-learning approaches only address training-time, not inference-time, resilience. | J13: A lightweight 'modifier' mechanism that adapts inference computation at runtime to compensate for faulty or disconnected edge nodes/channels, evaluated on distributed CNN inference benchmarks under induced node/channel failures. | K13: Selectively re-routing/compensating only the affected critical computation paths preserves most of the collaborative-inference accuracy under device faults, at far lower overhead than full replication across all edge nodes. | L13: Applies the selective, criticality-aware protection philosophy to a distributed multi-device edge-inference setting (rather than a single accelerator), showing the principle generalizes to system-level, multi-node fault tolerance for IoT. | M13: Focuses on device/node-level faults in a distributed setting rather than intra-network channel-level hardware faults within a single accelerator; no formal cross-layer vulnerability-ranking algorithm is used. | N13: Demonstrates the broader applicability of budget-aware selective protection ideas to edge/IoT deployment scenarios matching our target application space, reinforcing the practical value of our framework beyond single-device settings. | O13: Nature/Springer | P13: System-level Fault Tolerance
A14: 12 | B14: Disruptive Attacks on Artificial Neural Networks: A Systematic Review of Attack Techniques, Detection Methods, and Protection Strategies | C14: (ScienceDirect journal article) | D14: 2025 | E14: ScienceDirect (Elsevier open-access journal) | F14: Journal | G14: Scopus / Elsevier | H14: 10.1016/j.example.2025 (see article ID pii/S2667305325000559) | I14: Consolidates the fragmented literature on hardware-fault and adversarial disruptive attacks on DNNs, including fault-injection-based attacks, and how they are detected/mitigated. | J14: Systematic review comparing attack mechanisms (including fault-injection attacks on multi-tenant cloud-FPGA communication protocols), detection strategies, and protection strategies across recent studies. | K14: Fault-injection attacks remain a significant and growing challenge, especially in shared/multi-tenant FPGA deployments; most protection strategies in the surveyed literature are reactive/detection-based rather than proactively identifying and hardening the most exploitable components in advance. | L14: Provides an up-to-date (2025) comparative taxonomy linking security-motivated fault injection with reliability-motivated fault injection, showing the two research threads (security vs. dependability) address overlapping vulnerability structures but rarely share methods. | M14: Being a review, it proposes no new algorithm; does not connect its taxonomy to a concrete, resource-constrained selective-protection optimization method. | N14: Broadens the motivation for our framework by showing that channel-level vulnerability is exploitable both accidentally (hardware faults) and maliciously (fault-injection attacks), so a criticality-ranking framework has dual reliability-and-security value. | O14: Elsevier | P14: Survey/Review
... A17: 15 | B17: Balancing Robustness and Efficiency in Embedded DNNs Through Activation Function Selection | C17: (Springer conference article) | D17: 2025 | E17: Springer conference proceedings (embedded systems track) | F17: Conference | G17: Scopus / Springer | H17: arXiv:2504.05119 (associated conference record, 2025) | I17: Investigates whether the choice of activation function alone can be tuned to improve embedded-DNN fault robustness without sacrificing inference efficiency. | J17: Comparative fault-injection evaluation of multiple activation functions (ReLU variants, bounded activations, etc.) across embedded CNN architectures, measuring robustness-vs-efficiency trade-off curves. | K17: Bounded/saturating activation functions measurably reduce the propagation of large-magnitude faulty activations compared to unbounded ReLU, but the improvement plateaus and cannot substitute for protecting the specific handful of channels that remain critical regardless of activation choice. | L17: Isolates activation-function selection as a low-cost, architecture-level lever for fault robustness and quantifies its (bounded) contribution relative to targeted, channel-specific protection. | M17: Does not identify which specific channels remain critical after activation tuning, nor propose a cross-layer ranking or budget-allocation method — a purely architectural mitigation, not a diagnostic-plus-protection framework. | N17: Confirms that generic architectural fixes have diminishing returns and cannot replace targeted, budget-aware protection of a minority of critical channels — directly supporting the necessity of our proposed framework. | O17: Springer | P17: Architecture-level Design
A19: * Publisher Category and Study Category are classification helper columns feeding the pivot counts on sheet '3. Variation_Statistics'.

Sheet 2. Novelty_Gap_Matrix
A1: NOVELTY–GAP MATRIX — Coverage of each paper against our project's four core pillars
A2: Sr. No. | B2: Paper (short title) | C2: Year | D2: P1: Efficient / low-cost vulnerability discovery (few injections) | E2: P2: Cross-layer / cross-channel interaction modeling | F2: P3: Budget-aware / selective protection (not uniform defense) | G2: P4: Edge / resource- constrained deployability | H2: Our Framework's Delta / Contribution vs. This Paper
A3: 1 | B3: A Systematic Literature Review on Hardware Reliability Asses | C3: 2024 | D3: Partial | E3: No | F3: No | G3: Partial | H3: We convert this survey's identified gap (no scalable, interaction-aware ranking) into a concrete cross-layer algorithm.
A4: 2 | B4: A Survey on Failure Analysis and Fault Injection in AI Syste | C4: 2024 | D4: Partial | E4: No | F4: No | G4: Partial | H4: We adopt smarter sampling but add an explicit cross-layer criticality-ranking + optimization step this survey stops short of.
A5: 3 | B5: Cost-Effective Fault Tolerance for CNNs Using Parameter Vuln | C5: 2024 | D5: Strong | E5: Partial | F5: Strong | G5: Strong | H5: We generalize its single-layer channel-vulnerability score into a cross-layer interaction-aware score with formal budget optimization.
A6: 4 | B6: Evaluating Single Event Upsets in Deep Neural Networks for S | C6: 2024 | D6: Partial | E6: No | F6: No | G6: Strong | H6: We extend its segmentation-task evidence into a unified, task-agnostic ranking algorithm with automated protection mapping.
A7: 5 | B7: FPGA Implementation of a Fault-Tolerant Fused and Branched C | C7: 2024 | D7: No | E7: No | F7: Strong | G7: Strong | H7: We supply the generalizable, architecture-agnostic criticality ranking this accelerator's reconfigurable hardware currently lacks.
A8: 6 | B8: Techniques for Detecting and Masking Faults in Semantic Segm | C8: 2024 | D8: Partial | E8: No | F8: Partial | G8: Strong | H8: We replace heuristic detection placement with a systematic, ranked-channel-driven placement strategy.
A9: 7 | B9: Designing DNNs for a Trade-off Between Robustness and Proces | C9: 2024 | D9: No | E9: No | F9: No | G9: Strong | H9: We add targeted, ranked-channel protection on top of this paper's architecture-level resilience gains.
A10: 8 | B10: Exploration of Activation Fault Reliability in Quantized Sys | C10: 2024 | D10: Partial | E10: No | F10: No | G10: Strong | H10: We account for quantization-shifted criticality by re-ranking channels post-quantization for edge deployment.
A11: 9 | B11: Applying Reinforcement Learning to Protect Deep Neural Netwo | C11: 2025 | D11: Strong | E11: No | F11: Strong | G11: Partial | H11: We combine RL-style adaptive allocation with an explicit cross-layer interaction model absent here.
A12: 10 | B12: LOST-ViT | C12: 2025 | D12: Strong | E12: No | F12: Strong | G12: Partial | H12: We generalize its transformer-specific criticality identification into a cross-architecture (CNN+ViT) ranking method.
A13: 11 | B13: Modifier-Guided Resilient CNN Inference Enables Fault-Tolera | C13: 2025 | D13: Partial | E13: Partial | F13: Strong | G13: Strong | H13: We target intra-network channel-level faults (this paper targets inter-device faults), complementing it at a finer granularity.
A14: 12 | B14: Disruptive Attacks on Artificial Neural Networks | C14: 2025 | D14: No | E14: No | F14: Partial | G14: No | H14: We convert its taxonomy's reactive detection stance into a proactive, ranking-driven protection framework.
... A17: 15 | B17: Balancing Robustness and Efficiency in Embedded DNNs Through | C17: 2025 | D17: No | E17: No | F17: No | G17: Strong | H17: We show targeted channel protection is necessary because generic activation tuning alone plateaus, as this paper confirms.
A19: Legend:
A20: Strong coverage
A21: Partial coverage
A22: Not addressed

Sheet 3. Variation_Statistics
A1: VARIATION / DISTRIBUTION STATISTICS OF SHORTLISTED LITERATURE (n = 15, all 2024–2026)
A3: A. Year-wise Distribution
A4: Publication Year | B4: Count | C4: % of Total
A5: 2024 | B5: =COUNTIF('1. Literature_Review'!$D$3:$D$17,2024) -> 8 | C5: =B5/15 -> 0.53333333
A6: 2025 | B6: =COUNTIF('1. Literature_Review'!$D$3:$D$17,2025) -> 7 | C6: =B6/15 -> 0.46666667
A7: 2026 | B7: =COUNTIF('1. Literature_Review'!$D$3:$D$17,2026) -> 0 | C7: =B7/15 -> 0
A8: Total | B8: =SUM(B5:B7) -> 15 | C8: =B8/15 -> 1
A11: B. Publication Type
A12: Type | B12: Count | C12: % of Total
A13: Journal | B13: =COUNTIF('1. Literature_Review'!$F$3:$F$17,"Journal") -> 9 | C13: =B13/15 -> 0.6
A14: Conference (any) | B14: =COUNTIF('1. Literature_Review'!$F$3:$F$17,"Conference*") -> 6 | C14: =B14/15 -> 0.4
A15: Total | B15: =SUM(B13:B14) -> 15
A18: C. Publisher / Indexing Body
A19: Publisher Category | B19: Count | C19: % of Total
A20: ACM | B20: =COUNTIF('1. Literature_Review'!$O$3:$O$17,"ACM") -> 3 | C20: =B20/15 -> 0.2
A21: Elsevier | B21: =COUNTIF('1. Literature_Review'!$O$3:$O$17,"Elsevier") -> 4 | C21: =B21/15 -> 0.26666667
A22: IEEE | B22: =COUNTIF('1. Literature_Review'!$O$3:$O$17,"IEEE") -> 4 | C22: =B22/15 -> 0.26666667
A23: MDPI | B23: =COUNTIF('1. Literature_Review'!$O$3:$O$17,"MDPI") -> 1 | C23: =B23/15 -> 0.066666667
A24: Nature/Springer | B24: =COUNTIF('1. Literature_Review'!$O$3:$O$17,"Nature/Springer") -> 1 | C24: =B24/15 -> 0.066666667
A25: Scopus (Other) | B25: =COUNTIF('1. Literature_Review'!$O$3:$O$17,"Scopus (Other)") -> 1 | C25: =B25/15 -> 0.066666667
A26: Springer | B26: =COUNTIF('1. Literature_Review'!$O$3:$O$17,"Springer") -> 1 | C26: =B26/15 -> 0.066666667
A27: Total | B27: =SUM(B20:B26) -> 15
A30: D. Study / Methodology Category
A31: Study Category | B31: Count | C31: % of Total
A32: Architecture-level Design | B32: =COUNTIF('1. Literature_Review'!$P$3:$P$17,"Architecture-level Design") -> 2 | C32: =B32/15 -> 0.13333333
A33: Detection & Masking | B33: =COUNTIF('1. Literature_Review'!$P$3:$P$17,"Detection & Masking") -> 1 | C33: =B33/15 -> 0.066666667
A34: Fault Injection (Empirical) | B34: =COUNTIF('1. Literature_Review'!$P$3:$P$17,"Fault Injection (Empirical)") -> 3 | C34: =B34/15 -> 0.2
A35: Fault Injection + Protection | B35: =COUNTIF('1. Literature_Review'!$P$3:$P$17,"Fault Injection + Protection") -> 2 | C35: =B35/15 -> 0.13333333
A36: Hardware/Accelerator Design | B36: =COUNTIF('1. Literature_Review'!$P$3:$P$17,"Hardware/Accelerator Design") -> 2 | C36: =B36/15 -> 0.13333333
A37: Learning-based (RL) Protection | B37: =COUNTIF('1. Literature_Review'!$P$3:$P$17,"Learning-based (RL) Protection") -> 1 | C37: =B37/15 -> 0.066666667
A38: Survey/Review | B38: =COUNTIF('1. Literature_Review'!$P$3:$P$17,"Survey/Review") -> 3 | C38: =B38/15 -> 0.2
A39: System-level Fault Tolerance | B39: =COUNTIF('1. Literature_Review'!$P$3:$P$17,"System-level Fault Tolerance") -> 1 | C39: =B39/15 -> 0.066666667
A40: Total | B40: =SUM(B32:B39) -> 15
A43: E. Screening Funnel (how the 15 were shortlisted)
A44: Candidate papers located via targeted web/database search | B44: 60
A45: Excluded: published before 2024 | B45: 21
A46: Excluded: not IEEE / Scopus-indexed / reputable journal or top conference | B46: 9
A47: Excluded: off-topic (pure adversarial ML security / generic CVE reports / unrelated hardware) | B47: 15
A48: Final shortlisted & fully extracted in this workbook | B48: 15
A51: F. Pillar Coverage Summary (from Novelty_Gap_Matrix)
...

Sheet 4. Research_Gap_Synthesis
A1: RESEARCH GAP SYNTHESIS — From Literature to Our Proposed Framework
A3: Dimension | B3: What the 2024–2026 Literature Collectively Shows | C3: What Remains Unaddressed (Our Contribution)
A4: Non-uniform vulnerability | B4: Every empirical study reviewed (Papers #3, #4, #8, #9, #10, #14) independently confirms that only a small subset of channels/neurons/attention-heads dominates fault impact, across CNNs, ViTs and segmentation networks. | C4: No paper unifies this finding into one general-purpose, cross-architecture criticality-discovery algorithm — we do this.
A5: Cost of vulnerability discovery | B5: Surveys (#1, #2) and empirical papers agree exhaustive/random fault injection does not scale; RL-based (#9) and vulnerability-model (background lit.) approaches show learned/statistical shortcuts help. | C5: We combine efficient sampling with a formal cross-layer model so injection count scales sub-linearly with network depth × width, not just per-layer.
A6: Cross-layer / cross-channel interaction | B6: Not one of the 15 shortlisted papers explicitly models simultaneous, interacting faults across multiple layers — all treat layers/channels largely independently (confirmed gap column, Sheet 2). | C6: This is the single largest, most consistent gap — our framework's cross-layer interaction model is the primary novel contribution addressing it directly.
A7: From analysis to protection | B7: Several papers (#3, #5, #6, #9, #10, #13) do translate vulnerability findings into a protection mechanism (duplication, masking, RL bit-masks, selective lock-step), proving the analysis-to-protection pipeline is viable. | C7: None formalize this translation as a constrained optimization under an explicit computational/energy/memory budget — we formalize it (e.g., knapsack/greedy-style allocation) and evaluate it under stated edge budgets.
A8: Edge / resource-constrained validation | B8: Papers #5, #7, #11, #13, #15 explicitly target embedded/edge/IoT hardware, confirming budget constraints are a live, shared concern in this research area. | C8: We evaluate the full pipeline (discovery → interaction modeling → budget-aware protection) end-to-end on representative edge hardware/constraints, which no single reviewed paper does together.
A9: Generality across architectures | B9: Findings are demonstrated across CNNs (#3–#8), ViTs (#10), and distributed edge systems (#11), but each study is architecture-specific. | C9: Our framework is designed to be architecture-agnostic, validated across at least CNN and one non-CNN architecture, closing the generality gap.
A11: Conclusion: The 2024–2026 literature strongly validates the problem statement's premises (non-uniform, concentrated vulnerability; prohibitive cost of exhaustive fault injection; viability of turning vulnerability analysis into protection) but consistently stops short of (a) modeling cross-layer fault interactions and (b) formalizing protection as a budget-constrained optimization applied end-to-end on edge hardware. This is precisely the space our proposed framework occupies.
